Workbook

Sheet Master_Sheet
A1: Department of Computer Science & Engineering - Third Year Project Evaluation: MASTER SHEET | G1: EVALUATION-1 | R1: EVALUATION-2 | X1: EVALUATION-3 | AD1: GRAND TOTAL
A2: Evaluation-1 (30) = Presentation-1 (6, DPRC) + Presentation-2 (24, Evaluator rubric). Evaluation-2 (30) and Evaluation-3 (40) are fetched live from each Evaluator's own sheet. GRAND TOTAL (100) = Evaluation-1 + Evaluation-2 + Evaluation-3. Project Title is fetched from each guide's sheet (evaluators type it there for groups where it is blank). | G2: PRESENTATION-1 | H2: PRESENTATION-2
A3: Project_Id | B3: Project Title | C3: Guide | D3: Evaluator | E3: Member Roll No | F3: Member Name | G3: Problem Identification, Relevance, Objectives & Scope(6 Marks) | H3: Literature Review, Existing Work & Research Gap (6) | I3: Proposed Methodology, Technical Approach & Feasibility (6) | J3: Societal, Environmental, Sustainability & Ethical Considerations (6) | K3: Work Plan, Team Contribution & Initial Presentation (6) | L3: Review Marks (24) | M3: Total Marks (30) | N3: Fetch Check | O3: Guide (Filled) | P3: Presentation-1 Given? | Q3: Presentation-2 Given? | R3: Project Implementation & Application of Technical Knowledge (6) | S3: Problem Solving, Troubleshooting & Functional Development (6) | T3: Individual Contribution, Teamwork & Professional Practice (6) | U3: Societal, Environmental, Sustainability & Ethical Compliance (6) | V3: Progress Reporting, Presentation & Timeline Management (6) | W3: Evaluation-2 Total (30) | X3: Achievement of Objectives, Technical Quality & Implementation (8) | Y3: Testing, Validation, Results & Innovation (8) | Z3: Project Report, Documentation & Research Output (8) | AA3: Societal, Environmental, Sustainability & Ethical Impact (8) | AB3: Presentation, Viva & Individual Contribution (8) | AC3: Evaluation-3 Total (40) | AD3: GRAND TOTAL MARKS (100) | AE3: Evaluation-2 Given? | AF3: Evaluation-3 Given? | AG3: Project_Id (Filled) | AH3: Project Title (Filled) | AI3: Evaluator (Filled)
A4: P_001 | B4: =IF('Mr. Akhilesh Kumar Srivastava'!B4="","",'Mr. Akhilesh Kumar Srivastava'!B4) | C4: Mr. Abhishek Yadav | D4: Mr. Akhilesh Kumar Srivastava | E4: 2400320100481 | F4: Hardik Bhardwaj | G4: =IFERROR(INDEX('Evaluation-1'!$N$6:$N$436,MATCH($A4&"|"&$E4,'Evaluation-1'!$P$6:$P$436,0)),IFERROR(INDEX('Evaluation-1'!$N$6:$N$436,MATCH($E4,'Evaluation-1'!$G$6:$G$436,0)),"")) -> 4.2 | H4: =IF('Mr. Akhilesh Kumar Srivastava'!F4="","",'Mr. Akhilesh Kumar Srivastava'!F4) -> 6 | I4: =IF('Mr. Akhilesh Kumar Srivastava'!G4="","",'Mr. Akhilesh Kumar Srivastava'!G4) -> 6 | J4: =IF('Mr. Akhilesh Kumar Srivastava'!H4="","",'Mr. Akhilesh Kumar Srivastava'!H4) -> 6 | K4: =IF('Mr. Akhilesh Kumar Srivastava'!I4="","",'Mr. Akhilesh Kumar Srivastava'!I4) -> 6 | L4: =IF(COUNT(H4:K4)=0,"",SUM(H4:K4)) -> 24 | M4: =IF(COUNT(G4,L4)=0,"",ROUND(SUM(G4,L4),2)) -> 28.2 | N4: =IF($G4="","Not in Evaluation-1",IF(TRIM(LOWER(IFERROR(INDEX('Evaluation-1'!$H$6:$H$436,MATCH($A4&"|"&$E4,'Evaluation-1'!$P$6:$P$436,0)),INDEX('Evaluation-1'!$H$6:$H$436,MATCH($E4,'Evaluation-1'!$G$6:$G$436,0)))))=TRIM(LOWER($F4)),"OK","CHECK NAME")) -> OK | O4: =C4 -> Mr. Abhishek Yadav | P4: =IF(OR(ISNUMBER(IFERROR(INDEX('Evaluation-1'!$K$6:$K$436,MATCH($A4&"|"&$E4,'Evaluation-1'!$P$6:$P$436,0)),IFERROR(INDEX('Evaluation-1'!$K$6:$K$436,MATCH($E4,'Evaluation-1'!$G$6:$G$436,0)),""))),ISNUMBER(IFERROR(INDEX('Evaluation-1'!$L$6:$L$436,MATCH($A4&"|"&$E4,'Evaluation-1'!$P$6:$P$436,0)),IFERROR(INDEX('Evaluation-1'!$L$6:$L$436,MATCH($E4,'Evaluation-1'!$G$6:$G$436,0)),"")))),"Yes","No") -> Yes | Q4: =IF(L4<>"","Yes","No") -> Yes | R4: =IF('Mr. Akhilesh Kumar Srivastava'!M4="","",'Mr. Akhilesh Kumar Srivastava'!M4) | S4: =IF('Mr. Akhilesh Kumar Srivastava'!N4="","",'Mr. Akhilesh Kumar Srivastava'!N4) | T4: =IF('Mr. Akhilesh Kumar Srivastava'!O4="","",'Mr. Akhilesh Kumar Srivastava'!O4) | U4: =IF('Mr. Akhilesh Kumar Srivastava'!P4="","",'Mr. Akhilesh Kumar Srivastava'!P4) | V4: =IF('Mr. Akhilesh Kumar Srivastava'!Q4="","",'Mr. Akhilesh Kumar Srivastava'!Q4) | W4: =IF(COUNT(R4:V4)=0,"",SUM(R4:V4)) | X4: =IF('Mr. Akhilesh Kumar Srivastava'!S4="","",'Mr. Akhilesh Kumar Srivastava'!S4) | Y4: =IF('Mr. Akhilesh Kumar Srivastava'!T4="","",'Mr. Akhilesh Kumar Srivastava'!T4) | Z4: =IF('Mr. Akhilesh Kumar Srivastava'!U4="","",'Mr. Akhilesh Kumar Srivastava'!U4) | AA4: =IF('Mr. Akhilesh Kumar Srivastava'!V4="","",'Mr. Akhilesh Kumar Srivastava'!V4) | AB4: =IF('Mr. Akhilesh Kumar Srivastava'!W4="","",'Mr. Akhilesh Kumar Srivastava'!W4) | AC4: =IF(COUNT(X4:AB4)=0,"",SUM(X4:AB4)) | AD4: =IF(COUNT(M4,W4,AC4)=0,"",ROUND(SUM(M4,W4,AC4),2)) -> 28.2 | AE4: =IF(W4<>"","Yes","No") -> No | AF4: =IF(AC4<>"","Yes","No") -> No | AG4: =A4 -> P_001 | AH4: =B4 | AI4: =D4 -> Mr. Akhilesh Kumar Srivastava
E5: 2400320100439 | F5: Divyansh Chauhan | G5: =IFERROR(INDEX('Evaluation-1'!$N$6:$N$436,MATCH($A5&"|"&$E5,'Evaluation-1'!$P$6:$P$436,0)),IFERROR(INDEX('Evaluation-1'!$N$6:$N$436,MATCH($E5,'Evaluation-1'!$G$6:$G$436,0)),"")) -> 4.2 | H5: =IF('Mr. Akhilesh Kumar Srivastava'!F5="","",'Mr. Akhilesh Kumar Srivastava'!F5) | I5: =IF('Mr. Akhilesh Kumar Srivastava'!G5="","",'Mr. Akhilesh Kumar Srivastava'!G5) | J5: =IF('Mr. Akhilesh Kumar Srivastava'!H5="","",'Mr. Akhilesh Kumar Srivastava'!H5) | K5: =IF('Mr. Akhilesh Kumar Srivastava'!I5="","",'Mr. Akhilesh Kumar Srivastava'!I5) | L5: =IF(COUNT(H5:K5)=0,"",SUM(H5:K5)) | M5: =IF(COUNT(G5,L5)=0,"",ROUND(SUM(G5,L5),2)) -> 4.2 | N5: =IF($G5="","Not in Evaluation-1",IF(TRIM(LOWER(IFERROR(INDEX('Evaluation-1'!$H$6:$H$436,MATCH($A5&"|"&$E5,'Evaluation-1'!$P$6:$P$436,0)),INDEX('Evaluation-1'!$H$6:$H$436,MATCH($E5,'Evaluation-1'!$G$6:$G$436,0)))))=TRIM(LOWER($F5)),"OK","CHECK NAME")) -> OK | O5: =IF(C5<>"",C5,O4) -> Mr. Abhishek Yadav | P5: =IF(OR(ISNUMBER(IFERROR(INDEX('Evaluation-1'!$K$6:$K$436,MATCH($A5&"|"&$E5,'Evaluation-1'!$P$6:$P$436,0)),IFERROR(INDEX('Evaluation-1'!$K$6:$K$436,MATCH($E5,'Evaluation-1'!$G$6:$G$436,0)),""))),ISNUMBER(IFERROR(INDEX('Evaluation-1'!$L$6:$L$436,MATCH($A5&"|"&$E5,'Evaluation-1'!$P$6:$P$436,0)),IFERROR(INDEX('Evaluation-1'!$L$6:$L$436,MATCH($E5,'Evaluation-1'!$G$6:$G$436,0)),"")))),"Yes","No") -> Yes | Q5: =IF(L5<>"","Yes","No") -> No | R5: =IF('Mr. Akhilesh Kumar Srivastava'!M5="","",'Mr. Akhilesh Kumar Srivastava'!M5) | S5: =IF('Mr. Akhilesh Kumar Srivastava'!N5="","",'Mr. Akhilesh Kumar Srivastava'!N5) | T5: =IF('Mr. Akhilesh Kumar Srivastava'!O5="","",'Mr. Akhilesh Kumar Srivastava'!O5) | U5: =IF('Mr. Akhilesh Kumar Srivastava'!P5="","",'Mr. Akhilesh Kumar Srivastava'!P5) | V5: =IF('Mr. Akhilesh Kumar Srivastava'!Q5="","",'Mr. Akhilesh Kumar Srivastava'!Q5) | W5: =IF(COUNT(R5:V5)=0,"",SUM(R5:V5)) | X5: =IF('Mr. Akhilesh Kumar Srivastava'!S5="","",'Mr. Akhilesh Kumar Srivastava'!S5) | Y5: =IF('Mr. Akhilesh Kumar Srivastava'!T5="","",'Mr. Akhilesh Kumar Srivastava'!T5) | Z5: =IF('Mr. Akhilesh Kumar Srivastava'!U5="","",'Mr. Akhilesh Kumar Srivastava'!U5) | AA5: =IF('Mr. Akhilesh Kumar Srivastava'!V5="","",'Mr. Akhilesh Kumar Srivastava'!V5) | AB5: =IF('Mr. Akhilesh Kumar Srivastava'!W5="","",'Mr. Akhilesh Kumar Srivastava'!W5) | AC5: =IF(COUNT(X5:AB5)=0,"",SUM(X5:AB5)) | AD5: =IF(COUNT(M5,W5,AC5)=0,"",ROUND(SUM(M5,W5,AC5),2)) -> 4.2 | AE5: =IF(W5<>"","Yes","No") -> No | AF5: =IF(AC5<>"","Yes","No") -> No | AG5: =IF(A5<>"",A5,AG4) -> P_001 | AH5: =IF(B5<>"",B5,IF(A5<>"","",AH4)) | AI5: =IF(D5<>"",D5,AI4) -> Mr. Akhilesh Kumar Srivastava
E6: 2400320100486 | F6: Harsh Gupta | G6: =IFERROR(INDEX('Evaluation-1'!$N$6:$N$436,MATCH($A6&"|"&$E6,'Evaluation-1'!$P$6:$P$436,0)),IFERROR(INDEX('Evaluation-1'!$N$6:$N$436,MATCH($E6,'Evaluation-1'!$G$6:$G$436,0)),"")) -> 4.2 | H6: =IF('Mr. Akhilesh Kumar Srivastava'!F6="","",'Mr. Akhilesh Kumar Srivastava'!F6) | I6: =IF('Mr. Akhilesh Kumar Srivastava'!G6="","",'Mr. Akhilesh Kumar Srivastava'!G6) | J6: =IF('Mr. Akhilesh Kumar Srivastava'!H6="","",'Mr. Akhilesh Kumar Srivastava'!H6) | K6: =IF('Mr. Akhilesh Kumar Srivastava'!I6="","",'Mr. Akhilesh Kumar Srivastava'!I6) | L6: =IF(COUNT(H6:K6)=0,"",SUM(H6:K6)) | M6: =IF(COUNT(G6,L6)=0,"",ROUND(SUM(G6,L6),2)) -> 4.2 | N6: =IF($G6="","Not in Evaluation-1",IF(TRIM(LOWER(IFERROR(INDEX('Evaluation-1'!$H$6:$H$436,MATCH($A6&"|"&$E6,'Evaluation-1'!$P$6:$P$436,0)),INDEX('Evaluation-1'!$H$6:$H$436,MATCH($E6,'Evaluation-1'!$G$6:$G$436,0)))))=TRIM(LOWER($F6)),"OK","CHECK NAME")) -> OK | O6: =IF(C6<>"",C6,O5) -> Mr. Abhishek Yadav | P6: =IF(OR(ISNUMBER(IFERROR(INDEX('Evaluation-1'!$K$6:$K$436,MATCH($A6&"|"&$E6,'Evaluation-1'!$P$6:$P$436,0)),IFERROR(INDEX('Evaluation-1'!$K$6:$K$436,MATCH($E6,'Evaluation-1'!$G$6:$G$436,0)),""))),ISNUMBER(IFERROR(INDEX('Evaluation-1'!$L$6:$L$436,MATCH($A6&"|"&$E6,'Evaluation-1'!$P$6:$P$436,0)),IFERROR(INDEX('Evaluation-1'!$L$6:$L$436,MATCH($E6,'Evaluation-1'!$G$6:$G$436,0)),"")))),"Yes","No") -> Yes | Q6: =IF(L6<>"","Yes","No") -> No | R6: =IF('Mr. Akhilesh Kumar Srivastava'!M6="","",'Mr. Akhilesh Kumar Srivastava'!M6) | S6: =IF('Mr. Akhilesh Kumar Srivastava'!N6="","",'Mr. Akhilesh Kumar Srivastava'!N6) | T6: =IF('Mr. Akhilesh Kumar Srivastava'!O6="","",'Mr. Akhilesh Kumar Srivastava'!O6) | U6: =IF('Mr. Akhilesh Kumar Srivastava'!P6="","",'Mr. Akhilesh Kumar Srivastava'!P6) | V6: =IF('Mr. Akhilesh Kumar Srivastava'!Q6="","",'Mr. Akhilesh Kumar Srivastava'!Q6) | W6: =IF(COUNT(R6:V6)=0,"",SUM(R6:V6)) | X6: =IF('Mr. Akhilesh Kumar Srivastava'!S6="","",'Mr. Akhilesh Kumar Srivastava'!S6) | Y6: =IF('Mr. Akhilesh Kumar Srivastava'!T6="","",'Mr. Akhilesh Kumar Srivastava'!T6) | Z6: =IF('Mr. Akhilesh Kumar Srivastava'!U6="","",'Mr. Akhilesh Kumar Srivastava'!U6) | AA6: =IF('Mr. Akhilesh Kumar Srivastava'!V6="","",'Mr. Akhilesh Kumar Srivastava'!V6) | AB6: =IF('Mr. Akhilesh Kumar Srivastava'!W6="","",'Mr. Akhilesh Kumar Srivastava'!W6) | AC6: =IF(COUNT(X6:AB6)=0,"",SUM(X6:AB6)) | AD6: =IF(COUNT(M6,W6,AC6)=0,"",ROUND(SUM(M6,W6,AC6),2)) -> 4.2 | AE6: =IF(W6<>"","Yes","No") -> No | AF6: =IF(AC6<>"","Yes","No") -> No | AG6: =IF(A6<>"",A6,AG5) -> P_001 | AH6: =IF(B6<>"",B6,IF(A6<>"","",AH5)) | AI6: =IF(D6<>"",D6,AI5) -> Mr. Akhilesh Kumar Srivastava
E7: 2400320100769 | F7: Nitya Dutta | G7: =IFERROR(INDEX('Evaluation-1'!$N$6:$N$436,MATCH($A7&"|"&$E7,'Evaluation-1'!$P$6:$P$436,0)),IFERROR(INDEX('Evaluation-1'!$N$6:$N$436,MATCH($E7,'Evaluation-1'!$G$6:$G$436,0)),"")) -> 4.2 | H7: =IF('Mr. Akhilesh Kumar Srivastava'!F7="","",'Mr. Akhilesh Kumar Srivastava'!F7) | I7: =IF('Mr. Akhilesh Kumar Srivastava'!G7="","",'Mr. Akhilesh Kumar Srivastava'!G7) | J7: =IF('Mr. Akhilesh Kumar Srivastava'!H7="","",'Mr. Akhilesh Kumar Srivastava'!H7) | K7: =IF('Mr. Akhilesh Kumar Srivastava'!I7="","",'Mr. Akhilesh Kumar Srivastava'!I7) | L7: =IF(COUNT(H7:K7)=0,"",SUM(H7:K7)) | M7: =IF(COUNT(G7,L7)=0,"",ROUND(SUM(G7,L7),2)) -> 4.2 | N7: =IF($G7="","Not in Evaluation-1",IF(TRIM(LOWER(IFERROR(INDEX('Evaluation-1'!$H$6:$H$436,MATCH($A7&"|"&$E7,'Evaluation-1'!$P$6:$P$436,0)),INDEX('Evaluation-1'!$H$6:$H$436,MATCH($E7,'Evaluation-1'!$G$6:$G$436,0)))))=TRIM(LOWER($F7)),"OK","CHECK NAME")) -> OK | O7: =IF(C7<>"",C7,O6) -> Mr. Abhishek Yadav | P7: =IF(OR(ISNUMBER(IFERROR(INDEX('Evaluation-1'!$K$6:$K$436,MATCH($A7&"|"&$E7,'Evaluation-1'!$P$6:$P$436,0)),IFERROR(INDEX('Evaluation-1'!$K$6:$K$436,MATCH($E7,'Evaluation-1'!$G$6:$G$436,0)),""))),ISNUMBER(IFERROR(INDEX('Evaluation-1'!$L$6:$L$436,MATCH($A7&"|"&$E7,'Evaluation-1'!$P$6:$P$436,0)),IFERROR(INDEX('Evaluation-1'!$L$6:$L$436,MATCH($E7,'Evaluation-1'!$G$6:$G$436,0)),"")))),"Yes","No") -> Yes | Q7: =IF(L7<>"","Yes","No") -> No | R7: =IF('Mr. Akhilesh Kumar Srivastava'!M7="","",'Mr. Akhilesh Kumar Srivastava'!M7) | S7: =IF('Mr. Akhilesh Kumar Srivastava'!N7="","",'Mr. Akhilesh Kumar Srivastava'!N7) | T7: =IF('Mr. Akhilesh Kumar Srivastava'!O7="","",'Mr. Akhilesh Kumar Srivastava'!O7) | U7: =IF('Mr. Akhilesh Kumar Srivastava'!P7="","",'Mr. Akhilesh Kumar Srivastava'!P7) | V7: =IF('Mr. Akhilesh Kumar Srivastava'!Q7="","",'Mr. Akhilesh Kumar Srivastava'!Q7) | W7: =IF(COUNT(R7:V7)=0,"",SUM(R7:V7)) | X7: =IF('Mr. Akhilesh Kumar Srivastava'!S7="","",'Mr. Akhilesh Kumar Srivastava'!S7) | Y7: =IF('Mr. Akhilesh Kumar Srivastava'!T7="","",'Mr. Akhilesh Kumar Srivastava'!T7) | Z7: =IF('Mr. Akhilesh Kumar Srivastava'!U7="","",'Mr. Akhilesh Kumar Srivastava'!U7) | AA7: =IF('Mr. Akhilesh Kumar Srivastava'!V7="","",'Mr. Akhilesh Kumar Srivastava'!V7) | AB7: =IF('Mr. Akhilesh Kumar Srivastava'!W7="","",'Mr. Akhilesh Kumar Srivastava'!W7) | AC7: =IF(COUNT(X7:AB7)=0,"",SUM(X7:AB7)) | AD7: =IF(COUNT(M7,W7,AC7)=0,"",ROUND(SUM(M7,W7,AC7),2)) -> 4.2 | AE7: =IF(W7<>"","Yes","No") -> No | AF7: =IF(AC7<>"","Yes","No") -> No | AG7: =IF(A7<>"",A7,AG6) -> P_001 | AH7: =IF(B7<>"",B7,IF(A7<>"","",AH6)) | AI7: =IF(D7<>"",D7,AI6) -> Mr. Akhilesh Kumar Srivastava
A8: P_002 | B8: =IF('Mr. Akhilesh Kumar Srivastava'!B8="","",'Mr. Akhilesh Kumar Srivastava'!B8) | E8: 2400320100468 | F8: Gaurav singh | G8: =IFERROR(INDEX('Evaluation-1'!$N$6:$N$436,MATCH($A8&"|"&$E8,'Evaluation-1'!$P$6:$P$436,0)),IFERROR(INDEX('Evaluation-1'!$N$6:$N$436,MATCH($E8,'Evaluation-1'!$G$6:$G$436,0)),"")) -> 4.2 | H8: =IF('Mr. Akhilesh Kumar Srivastava'!F8="","",'Mr. Akhilesh Kumar Srivastava'!F8) | I8: =IF('Mr. Akhilesh Kumar Srivastava'!G8="","",'Mr. Akhilesh Kumar Srivastava'!G8) | J8: =IF('Mr. Akhilesh Kumar Srivastava'!H8="","",'Mr. Akhilesh Kumar Srivastava'!H8) | K8: =IF('Mr. Akhilesh Kumar Srivastava'!I8="","",'Mr. Akhilesh Kumar Srivastava'!I8) | L8: =IF(COUNT(H8:K8)=0,"",SUM(H8:K8)) | M8: =IF(COUNT(G8,L8)=0,"",ROUND(SUM(G8,L8),2)) -> 4.2 | N8: =IF($G8="","Not in Evaluation-1",IF(TRIM(LOWER(IFERROR(INDEX('Evaluation-1'!$H$6:$H$436,MATCH($A8&"|"&$E8,'Evaluation-1'!$P$6:$P$436,0)),INDEX('Evaluation-1'!$H$6:$H$436,MATCH($E8,'Evaluation-1'!$G$6:$G$436,0)))))=TRIM(LOWER($F8)),"OK","CHECK NAME")) -> OK | O8: =IF(C8<>"",C8,O7) -> Mr. Abhishek Yadav | P8: =IF(OR(ISNUMBER(IFERROR(INDEX('Evaluation-1'!$K$6:$K$436,MATCH($A8&"|"&$E8,'Evaluation-1'!$P$6:$P$436,0)),IFERROR(INDEX('Evaluation-1'!$K$6:$K$436,MATCH($E8,'Evaluation-1'!$G$6:$G$436,0)),""))),ISNUMBER(IFERROR(INDEX('Evaluation-1'!$L$6:$L$436,MATCH($A8&"|"&$E8,'Evaluation-1'!$P$6:$P$436,0)),IFERROR(INDEX('Evaluation-1'!$L$6:$L$436,MATCH($E8,'Evaluation-1'!$G$6:$G$436,0)),"")))),"Yes","No") -> Yes | Q8: =IF(L8<>"","Yes","No") -> No | R8: =IF('Mr. Akhilesh Kumar Srivastava'!M8="","",'Mr. Akhilesh Kumar Srivastava'!M8) | S8: =IF('Mr. Akhilesh Kumar Srivastava'!N8="","",'Mr. Akhilesh Kumar Srivastava'!N8) | T8: =IF('Mr. Akhilesh Kumar Srivastava'!O8="","",'Mr. Akhilesh Kumar Srivastava'!O8) | U8: =IF('Mr. Akhilesh Kumar Srivastava'!P8="","",'Mr. Akhilesh Kumar Srivastava'!P8) | V8: =IF('Mr. Akhilesh Kumar Srivastava'!Q8="","",'Mr. Akhilesh Kumar Srivastava'!Q8) | W8: =IF(COUNT(R8:V8)=0,"",SUM(R8:V8)) | X8: =IF('Mr. Akhilesh Kumar Srivastava'!S8="","",'Mr. Akhilesh Kumar Srivastava'!S8) | Y8: =IF('Mr. Akhilesh Kumar Srivastava'!T8="","",'Mr. Akhilesh Kumar Srivastava'!T8) | Z8: =IF('Mr. Akhilesh Kumar Srivastava'!U8="","",'Mr. Akhilesh Kumar Srivastava'!U8) | AA8: =IF('Mr. Akhilesh Kumar Srivastava'!V8="","",'Mr. Akhilesh Kumar Srivastava'!V8) | AB8: =IF('Mr. Akhilesh Kumar Srivastava'!W8="","",'Mr. Akhilesh Kumar Srivastava'!W8) | AC8: =IF(COUNT(X8:AB8)=0,"",SUM(X8:AB8)) | AD8: =IF(COUNT(M8,W8,AC8)=0,"",ROUND(SUM(M8,W8,AC8),2)) -> 4.2 | AE8: =IF(W8<>"","Yes","No") -> No | AF8: =IF(AC8<>"","Yes","No") -> No | AG8: =IF(A8<>"",A8,AG7) -> P_002 | AH8: =IF(B8<>"",B8,IF(A8<>"","",AH7)) | AI8: =IF(D8<>"",D8,AI7) -> Mr. Akhilesh Kumar Srivastava
E9: 2400320100564 | F9: Karn singh | G9: =IFERROR(INDEX('Evaluation-1'!$N$6:$N$436,MATCH($A9&"|"&$E9,'Evaluation-1'!$P$6:$P$436,0)),IFERROR(INDEX('Evaluation-1'!$N$6:$N$436,MATCH($E9,'Evaluation-1'!$G$6:$G$436,0)),"")) -> 4.2 | H9: =IF('Mr. Akhilesh Kumar Srivastava'!F9="","",'Mr. Akhilesh Kumar Srivastava'!F9) | I9: =IF('Mr. Akhilesh Kumar Srivastava'!G9="","",'Mr. Akhilesh Kumar Srivastava'!G9) | J9: =IF('Mr. Akhilesh Kumar Srivastava'!H9="","",'Mr. Akhilesh Kumar Srivastava'!H9) | K9: =IF('Mr. Akhilesh Kumar Srivastava'!I9="","",'Mr. Akhilesh Kumar Srivastava'!I9) | L9: =IF(COUNT(H9:K9)=0,"",SUM(H9:K9)) | M9: =IF(COUNT(G9,L9)=0,"",ROUND(SUM(G9,L9),2)) -> 4.2 | N9: =IF($G9="","Not in Evaluation-1",IF(TRIM(LOWER(IFERROR(INDEX('Evaluation-1'!$H$6:$H$436,MATCH($A9&"|"&$E9,'Evaluation-1'!$P$6:$P$436,0)),INDEX('Evaluation-1'!$H$6:$H$436,MATCH($E9,'Evaluation-1'!$G$6:$G$436,0)))))=TRIM(LOWER($F9)),"OK","CHECK NAME")) -> OK | O9: =IF(C9<>"",C9,O8) -> Mr. Abhishek Yadav | P9: =IF(OR(ISNUMBER(IFERROR(INDEX('Evaluation-1'!$K$6:$K$436,MATCH($A9&"|"&$E9,'Evaluation-1'!$P$6:$P$436,0)),IFERROR(INDEX('Evaluation-1'!$K$6:$K$436,MATCH($E9,'Evaluation-1'!$G$6:$G$436,0)),""))),ISNUMBER(IFERROR(INDEX('Evaluation-1'!$L$6:$L$436,MATCH($A9&"|"&$E9,'Evaluation-1'!$P$6:$P$436,0)),IFERROR(INDEX('Evaluation-1'!$L$6:$L$436,MATCH($E9,'Evaluation-1'!$G$6:$G$436,0)),"")))),"Yes","No") -> Yes | Q9: =IF(L9<>"","Yes","No") -> No | R9: =IF('Mr. Akhilesh Kumar Srivastava'!M9="","",'Mr. Akhilesh Kumar Srivastava'!M9) | S9: =IF('Mr. Akhilesh Kumar Srivastava'!N9="","",'Mr. Akhilesh Kumar Srivastava'!N9) | T9: =IF('Mr. Akhilesh Kumar Srivastava'!O9="","",'Mr. Akhilesh Kumar Srivastava'!O9) | U9: =IF('Mr. Akhilesh Kumar Srivastava'!P9="","",'Mr. Akhilesh Kumar Srivastava'!P9) | V9: =IF('Mr. Akhilesh Kumar Srivastava'!Q9="","",'Mr. Akhilesh Kumar Srivastava'!Q9) | W9: =IF(COUNT(R9:V9)=0,"",SUM(R9:V9)) | X9: =IF('Mr. Akhilesh Kumar Srivastava'!S9="","",'Mr. Akhilesh Kumar Srivastava'!S9) | Y9: =IF('Mr. Akhilesh Kumar Srivastava'!T9="","",'Mr. Akhilesh Kumar Srivastava'!T9) | Z9: =IF('Mr. Akhilesh Kumar Srivastava'!U9="","",'Mr. Akhilesh Kumar Srivastava'!U9) | AA9: =IF('Mr. Akhilesh Kumar Srivastava'!V9="","",'Mr. Akhilesh Kumar Srivastava'!V9) | AB9: =IF('Mr. Akhilesh Kumar Srivastava'!W9="","",'Mr. Akhilesh Kumar Srivastava'!W9) | AC9: =IF(COUNT(X9:AB9)=0,"",SUM(X9:AB9)) | AD9: =IF(COUNT(M9,W9,AC9)=0,"",ROUND(SUM(M9,W9,AC9),2)) -> 4.2 | AE9: =IF(W9<>"","Yes","No") -> No | AF9: =IF(AC9<>"","Yes","No") -> No | AG9: =IF(A9<>"",A9,AG8) -> P_002 | AH9: =IF(B9<>"",B9,IF(A9<>"","",AH8)) | AI9: =IF(D9<>"",D9,AI8) -> Mr. Akhilesh Kumar Srivastava
E10: 2400320100566 | F10: Kartik Bharadwaj | G10: =IFERROR(INDEX('Evaluation-1'!$N$6:$N$436,MATCH($A10&"|"&$E10,'Evaluation-1'!$P$6:$P$436,0)),IFERROR(INDEX('Evaluation-1'!$N$6:$N$436,MATCH($E10,'Evaluation-1'!$G$6:$G$436,0)),"")) -> 4.2 | H10: =IF('Mr. Akhilesh Kumar Srivastava'!F10="","",'Mr. Akhilesh Kumar Srivastava'!F10) | I10: =IF('Mr. Akhilesh Kumar Srivastava'!G10="","",'Mr. Akhilesh Kumar Srivastava'!G10) | J10: =IF('Mr. Akhilesh Kumar Srivastava'!H10="","",'Mr. Akhilesh Kumar Srivastava'!H10) | K10: =IF('Mr. Akhilesh Kumar Srivastava'!I10="","",'Mr. Akhilesh Kumar Srivastava'!I10) | L10: =IF(COUNT(H10:K10)=0,"",SUM(H10:K10)) | M10: =IF(COUNT(G10,L10)=0,"",ROUND(SUM(G10,L10),2)) -> 4.2 | N10: =IF($G10="","Not in Evaluation-1",IF(TRIM(LOWER(IFERROR(INDEX('Evaluation-1'!$H$6:$H$436,MATCH($A10&"|"&$E10,'Evaluation-1'!$P$6:$P$436,0)),INDEX('Evaluation-1'!$H$6:$H$436,MATCH($E10,'Evaluation-1'!$G$6:$G$436,0)))))=TRIM(LOWER($F10)),"OK","CHECK NAME")) -> OK | O10: =IF(C10<>"",C10,O9) -> Mr. Abhishek Yadav | P10: =IF(OR(ISNUMBER(IFERROR(INDEX('Evaluation-1'!$K$6:$K$436,MATCH($A10&"|"&$E10,'Evaluation-1'!$P$6:$P$436,0)),IFERROR(INDEX('Evaluation-1'!$K$6:$K$436,MATCH($E10,'Evaluation-1'!$G$6:$G$436,0)),""))),ISNUMBER(IFERROR(INDEX('Evaluation-1'!$L$6:$L$436,MATCH($A10&"|"&$E10,'Evaluation-1'!$P$6:$P$436,0)),IFERROR(INDEX('Evaluation-1'!$L$6:$L$436,MATCH($E10,'Evaluation-1'!$G$6:$G$436,0)),"")))),"Yes","No") -> Yes | Q10: =IF(L10<>"","Yes","No") -> No | R10: =IF('Mr. Akhilesh Kumar Srivastava'!M10="","",'Mr. Akhilesh Kumar Srivastava'!M10) | S10: =IF('Mr. Akhilesh Kumar Srivastava'!N10="","",'Mr. Akhilesh Kumar Srivastava'!N10) | T10: =IF('Mr. Akhilesh Kumar Srivastava'!O10="","",'Mr. Akhilesh Kumar Srivastava'!O10) | U10: =IF('Mr. Akhilesh Kumar Srivastava'!P10="","",'Mr. Akhilesh Kumar Srivastava'!P10) | V10: =IF('Mr. Akhilesh Kumar Srivastava'!Q10="","",'Mr. Akhilesh Kumar Srivastava'!Q10) | W10: =IF(COUNT(R10:V10)=0,"",SUM(R10:V10)) | X10: =IF('Mr. Akhilesh Kumar Srivastava'!S10="","",'Mr. Akhilesh Kumar Srivastava'!S10) | Y10: =IF('Mr. Akhilesh Kumar Srivastava'!T10="","",'Mr. Akhilesh Kumar Srivastava'!T10) | Z10: =IF('Mr. Akhilesh Kumar Srivastava'!U10="","",'Mr. Akhilesh Kumar Srivastava'!U10) | AA10: =IF('Mr. Akhilesh Kumar Srivastava'!V10="","",'Mr. Akhilesh Kumar Srivastava'!V10) | AB10: =IF('Mr. Akhilesh Kumar Srivastava'!W10="","",'Mr. Akhilesh Kumar Srivastava'!W10) | AC10: =IF(COUNT(X10:AB10)=0,"",SUM(X10:AB10)) | AD10: =IF(COUNT(M10,W10,AC10)=0,"",ROUND(SUM(M10,W10,AC10),2)) -> 4.2 | AE10: =IF(W10<>"","Yes","No") -> No | AF10: =IF(AC10<>"","Yes","No") -> No | AG10: =IF(A10<>"",A10,AG9) -> P_002 | AH10: =IF(B10<>"",B10,IF(A10<>"","",AH9)) | AI10: =IF(D10<>"",D10,AI9) -> Mr. Akhilesh Kumar Srivastava
E11: 2400320100547 | F11: Jay Prakash Yadav | G11: =IFERROR(INDEX('Evaluation-1'!$N$6:$N$436,MATCH($A11&"|"&$E11,'Evaluation-1'!$P$6:$P$436,0)),IFERROR(INDEX('Evaluation-1'!$N$6:$N$436,MATCH($E11,'Evaluation-1'!$G$6:$G$436,0)),"")) -> 4.2 | H11: =IF('Mr. Akhilesh Kumar Srivastava'!F11="","",'Mr. Akhilesh Kumar Srivastava'!F11) | I11: =IF('Mr. Akhilesh Kumar Srivastava'!G11="","",'Mr. Akhilesh Kumar Srivastava'!G11) | J11: =IF('Mr. Akhilesh Kumar Srivastava'!H11="","",'Mr. Akhilesh Kumar Srivastava'!H11) | K11: =IF('Mr. Akhilesh Kumar Srivastava'!I11="","",'Mr. Akhilesh Kumar Srivastava'!I11) | L11: =IF(COUNT(H11:K11)=0,"",SUM(H11:K11)) | M11: =IF(COUNT(G11,L11)=0,"",ROUND(SUM(G11,L11),2)) -> 4.2 | N11: =IF($G11="","Not in Evaluation-1",IF(TRIM(LOWER(IFERROR(INDEX('Evaluation-1'!$H$6:$H$436,MATCH($A11&"|"&$E11,'Evaluation-1'!$P$6:$P$436,0)),INDEX('Evaluation-1'!$H$6:$H$436,MATCH($E11,'Evaluation-1'!$G$6:$G$436,0)))))=TRIM(LOWER($F11)),"OK","CHECK NAME")) -> OK | O11: =IF(C11<>"",C11,O10) -> Mr. Abhishek Yadav | P11: =IF(OR(ISNUMBER(IFERROR(INDEX('Evaluation-1'!$K$6:$K$436,MATCH($A11&"|"&$E11,'Evaluation-1'!$P$6:$P$436,0)),IFERROR(INDEX('Evaluation-1'!$K$6:$K$436,MATCH($E11,'Evaluation-1'!$G$6:$G$436,0)),""))),ISNUMBER(IFERROR(INDEX('Evaluation-1'!$L$6:$L$436,MATCH($A11&"|"&$E11,'Evaluation-1'!$P$6:$P$436,0)),IFERROR(INDEX('Evaluation-1'!$L$6:$L$436,MATCH($E11,'Evaluation-1'!$G$6:$G$436,0)),"")))),"Yes","No") -> Yes | Q11: =IF(L11<>"","Yes","No") -> No | R11: =IF('Mr. Akhilesh Kumar Srivastava'!M11="","",'Mr. Akhilesh Kumar Srivastava'!M11) | S11: =IF('Mr. Akhilesh Kumar Srivastava'!N11="","",'Mr. Akhilesh Kumar Srivastava'!N11) | T11: =IF('Mr. Akhilesh Kumar Srivastava'!O11="","",'Mr. Akhilesh Kumar Srivastava'!O11) | U11: =IF('Mr. Akhilesh Kumar Srivastava'!P11="","",'Mr. Akhilesh Kumar Srivastava'!P11) | V11: =IF('Mr. Akhilesh Kumar Srivastava'!Q11="","",'Mr. Akhilesh Kumar Srivastava'!Q11) | W11: =IF(COUNT(R11:V11)=0,"",SUM(R11:V11)) | X11: =IF('Mr. Akhilesh Kumar Srivastava'!S11="","",'Mr. Akhilesh Kumar Srivastava'!S11) | Y11: =IF('Mr. Akhilesh Kumar Srivastava'!T11="","",'Mr. Akhilesh Kumar Srivastava'!T11) | Z11: =IF('Mr. Akhilesh Kumar Srivastava'!U11="","",'Mr. Akhilesh Kumar Srivastava'!U11) | AA11: =IF('Mr. Akhilesh Kumar Srivastava'!V11="","",'Mr. Akhilesh Kumar Srivastava'!V11) | AB11: =IF('Mr. Akhilesh Kumar Srivastava'!W11="","",'Mr. Akhilesh Kumar Srivastava'!W11) | AC11: =IF(COUNT(X11:AB11)=0,"",SUM(X11:AB11)) | AD11: =IF(COUNT(M11,W11,AC11)=0,"",ROUND(SUM(M11,W11,AC11),2)) -> 4.2 | AE11: =IF(W11<>"","Yes","No") -> No | AF11: =IF(AC11<>"","Yes","No") -> No | AG11: =IF(A11<>"",A11,AG10) -> P_002 | AH11: =IF(B11<>"",B11,IF(A11<>"","",AH10)) | AI11: =IF(D11<>"",D11,AI10) -> Mr. Akhilesh Kumar Srivastava
A12: P_003 | B12: =IF('Mr. Akhilesh Kumar Srivastava'!B12="","",'Mr. Akhilesh Kumar Srivastava'!B12) | E12: 2400320100866 | F12: Pushkar Khandelwal | G12: =IFERROR(INDEX('Evaluation-1'!$N$6:$N$436,MATCH($A12&"|"&$E12,'Evaluation-1'!$P$6:$P$436,0)),IFERROR(INDEX('Evaluation-1'!$N$6:$N$436,MATCH($E12,'Evaluation-1'!$G$6:$G$436,0)),"")) -> 4.8 | H12: =IF('Mr. Akhilesh Kumar Srivastava'!F12="","",'Mr. Akhilesh Kumar Srivastava'!F12) | I12: =IF('Mr. Akhilesh Kumar Srivastava'!G12="","",'Mr. Akhilesh Kumar Srivastava'!G12) | J12: =IF('Mr. Akhilesh Kumar Srivastava'!H12="","",'Mr. Akhilesh Kumar Srivastava'!H12) | K12: =IF('Mr. Akhilesh Kumar Srivastava'!I12="","",'Mr. Akhilesh Kumar Srivastava'!I12) | L12: =IF(COUNT(H12:K12)=0,"",SUM(H12:K12)) | M12: =IF(COUNT(G12,L12)=0,"",ROUND(SUM(G12,L12),2)) -> 4.8 | N12: =IF($G12="","Not in Evaluation-1",IF(TRIM(LOWER(IFERROR(INDEX('Evaluation-1'!$H$6:$H$436,MATCH($A12&"|"&$E12,'Evaluation-1'!$P$6:$P$436,0)),INDEX('Evaluation-1'!$H$6:$H$436,MATCH($E12,'Evaluation-1'!$G$6:$G$436,0)))))=TRIM(LOWER($F12)),"OK","CHECK NAME")) -> OK | O12: =IF(C12<>"",C12,O11) -> Mr. Abhishek Yadav | P12: =IF(OR(ISNUMBER(IFERROR(INDEX('Evaluation-1'!$K$6:$K$436,MATCH($A12&"|"&$E12,'Evaluation-1'!$P$6:$P$436,0)),IFERROR(INDEX('Evaluation-1'!$K$6:$K$436,MATCH($E12,'Evaluation-1'!$G$6:$G$436,0)),""))),ISNUMBER(IFERROR(INDEX('Evaluation-1'!$L$6:$L$436,MATCH($A12&"|"&$E12,'Evaluation-1'!$P$6:$P$436,0)),IFERROR(INDEX('Evaluation-1'!$L$6:$L$436,MATCH($E12,'Evaluation-1'!$G$6:$G$436,0)),"")))),"Yes","No") -> Yes | Q12: =IF(L12<>"","Yes","No") -> No | R12: =IF('Mr. Akhilesh Kumar Srivastava'!M12="","",'Mr. Akhilesh Kumar Srivastava'!M12) | S12: =IF('Mr. Akhilesh Kumar Srivastava'!N12="","",'Mr. Akhilesh Kumar Srivastava'!N12) | T12: =IF('Mr. Akhilesh Kumar Srivastava'!O12="","",'Mr. Akhilesh Kumar Srivastava'!O12) | U12: =IF('Mr. Akhilesh Kumar Srivastava'!P12="","",'Mr. Akhilesh Kumar Srivastava'!P12) | V12: =IF('Mr. Akhilesh Kumar Srivastava'!Q12="","",'Mr. Akhilesh Kumar Srivastava'!Q12) | W12: =IF(COUNT(R12:V12)=0,"",SUM(R12:V12)) | X12: =IF('Mr. Akhilesh Kumar Srivastava'!S12="","",'Mr. Akhilesh Kumar Srivastava'!S12) | Y12: =IF('Mr. Akhilesh Kumar Srivastava'!T12="","",'Mr. Akhilesh Kumar Srivastava'!T12) | Z12: =IF('Mr. Akhilesh Kumar Srivastava'!U12="","",'Mr. Akhilesh Kumar Srivastava'!U12) | AA12: =IF('Mr. Akhilesh Kumar Srivastava'!V12="","",'Mr. Akhilesh Kumar Srivastava'!V12) | AB12: =IF('Mr. Akhilesh Kumar Srivastava'!W12="","",'Mr. Akhilesh Kumar Srivastava'!W12) | AC12: =IF(COUNT(X12:AB12)=0,"",SUM(X12:AB12)) | AD12: =IF(COUNT(M12,W12,AC12)=0,"",ROUND(SUM(M12,W12,AC12),2)) -> 4.8 | AE12: =IF(W12<>"","Yes","No") -> No | AF12: =IF(AC12<>"","Yes","No") -> No | AG12: =IF(A12<>"",A12,AG11) -> P_003 | AH12: =IF(B12<>"",B12,IF(A12<>"","",AH11)) | AI12: =IF(D12<>"",D12,AI11) -> Mr. Akhilesh Kumar Srivastava
E13: 2400320100788 | F13: Parth Gupta | G13: =IFERROR(INDEX('Evaluation-1'!$N$6:$N$436,MATCH($A13&"|"&$E13,'Evaluation-1'!$P$6:$P$436,0)),IFERROR(INDEX('Evaluation-1'!$N$6:$N$436,MATCH($E13,'Evaluation-1'!$G$6:$G$436,0)),"")) -> 4.8 | H13: =IF('Mr. Akhilesh Kumar Srivastava'!F13="","",'Mr. Akhilesh Kumar Srivastava'!F13) | I13: =IF('Mr. Akhilesh Kumar Srivastava'!G13="","",'Mr. Akhilesh Kumar Srivastava'!G13) | J13: =IF('Mr. Akhilesh Kumar Srivastava'!H13="","",'Mr. Akhilesh Kumar Srivastava'!H13) | K13: =IF('Mr. Akhilesh Kumar Srivastava'!I13="","",'Mr. Akhilesh Kumar Srivastava'!I13) | L13: =IF(COUNT(H13:K13)=0,"",SUM(H13:K13)) | M13: =IF(COUNT(G13,L13)=0,"",ROUND(SUM(G13,L13),2)) -> 4.8 | N13: =IF($G13="","Not in Evaluation-1",IF(TRIM(LOWER(IFERROR(INDEX('Evaluation-1'!$H$6:$H$436,MATCH($A13&"|"&$E13,'Evaluation-1'!$P$6:$P$436,0)),INDEX('Evaluation-1'!$H$6:$H$436,MATCH($E13,'Evaluation-1'!$G$6:$G$436,0)))))=TRIM(LOWER($F13)),"OK","CHECK NAME")) -> OK | O13: =IF(C13<>"",C13,O12) -> Mr. Abhishek Yadav | P13: =IF(OR(ISNUMBER(IFERROR(INDEX('Evaluation-1'!$K$6:$K$436,MATCH($A13&"|"&$E13,'Evaluation-1'!$P$6:$P$436,0)),IFERROR(INDEX('Evaluation-1'!$K$6:$K$436,MATCH($E13,'Evaluation-1'!$G$6:$G$436,0)),""))),ISNUMBER(IFERROR(INDEX('Evaluation-1'!$L$6:$L$436,MATCH($A13&"|"&$E13,'Evaluation-1'!$P$6:$P$436,0)),IFERROR(INDEX('Evaluation-1'!$L$6:$L$436,MATCH($E13,'Evaluation-1'!$G$6:$G$436,0)),"")))),"Yes","No") -> Yes | Q13: =IF(L13<>"","Yes","No") -> No | R13: =IF('Mr. Akhilesh Kumar Srivastava'!M13="","",'Mr. Akhilesh Kumar Srivastava'!M13) | S13: =IF('Mr. Akhilesh Kumar Srivastava'!N13="","",'Mr. Akhilesh Kumar Srivastava'!N13) | T13: =IF('Mr. Akhilesh Kumar Srivastava'!O13="","",'Mr. Akhilesh Kumar Srivastava'!O13) | U13: =IF('Mr. Akhilesh Kumar Srivastava'!P13="","",'Mr. Akhilesh Kumar Srivastava'!P13) | V13: =IF('Mr. Akhilesh Kumar Srivastava'!Q13="","",'Mr. Akhilesh Kumar Srivastava'!Q13) | W13: =IF(COUNT(R13:V13)=0,"",SUM(R13:V13)) | X13: =IF('Mr. Akhilesh Kumar Srivastava'!S13="","",'Mr. Akhilesh Kumar Srivastava'!S13) | Y13: =IF('Mr. Akhilesh Kumar Srivastava'!T13="","",'Mr. Akhilesh Kumar Srivastava'!T13) | Z13: =IF('Mr. Akhilesh Kumar Srivastava'!U13="","",'Mr. Akhilesh Kumar Srivastava'!U13) | AA13: =IF('Mr. Akhilesh Kumar Srivastava'!V13="","",'Mr. Akhilesh Kumar Srivastava'!V13) | AB13: =IF('Mr. Akhilesh Kumar Srivastava'!W13="","",'Mr. Akhilesh Kumar Srivastava'!W13) | AC13: =IF(COUNT(X13:AB13)=0,"",SUM(X13:AB13)) | AD13: =IF(COUNT(M13,W13,AC13)=0,"",ROUND(SUM(M13,W13,AC13),2)) -> 4.8 | AE13: =IF(W13<>"","Yes","No") -> No | AF13: =IF(AC13<>"","Yes","No") -> No | AG13: =IF(A13<>"",A13,AG12) -> P_003 | AH13: =IF(B13<>"",B13,IF(A13<>"","",AH12)) | AI13: =IF(D13<>"",D13,AI12) -> Mr. Akhilesh Kumar Srivastava
E14: 2400320100764 | F14: Nitin Chauhan | G14: =IFERROR(INDEX('Evaluation-1'!$N$6:$N$436,MATCH($A14&"|"&$E14,'Evaluation-1'!$P$6:$P$436,0)),IFERROR(INDEX('Evaluation-1'!$N$6:$N$436,MATCH($E14,'Evaluation-1'!$G$6:$G$436,0)),"")) -> 4.8 | H14: =IF('Mr. Akhilesh Kumar Srivastava'!F14="","",'Mr. Akhilesh Kumar Srivastava'!F14) | I14: =IF('Mr. Akhilesh Kumar Srivastava'!G14="","",'Mr. Akhilesh Kumar Srivastava'!G14) | J14: =IF('Mr. Akhilesh Kumar Srivastava'!H14="","",'Mr. Akhilesh Kumar Srivastava'!H14) | K14: =IF('Mr. Akhilesh Kumar Srivastava'!I14="","",'Mr. Akhilesh Kumar Srivastava'!I14) | L14: =IF(COUNT(H14:K14)=0,"",SUM(H14:K14)) | M14: =IF(COUNT(G14,L14)=0,"",ROUND(SUM(G14,L14),2)) -> 4.8 | N14: =IF($G14="","Not in Evaluation-1",IF(TRIM(LOWER(IFERROR(INDEX('Evaluation-1'!$H$6:$H$436,MATCH($A14&"|"&$E14,'Evaluation-1'!$P$6:$P$436,0)),INDEX('Evaluation-1'!$H$6:$H$436,MATCH($E14,'Evaluation-1'!$G$6:$G$436,0)))))=TRIM(LOWER($F14)),"OK","CHECK NAME")) -> OK | O14: =IF(C14<>"",C14,O13) -> Mr. Abhishek Yadav | P14: =IF(OR(ISNUMBER(IFERROR(INDEX('Evaluation-1'!$K$6:$K$436,MATCH($A14&"|"&$E14,'Evaluation-1'!$P$6:$P$436,0)),IFERROR(INDEX('Evaluation-1'!$K$6:$K$436,MATCH($E14,'Evaluation-1'!$G$6:$G$436,0)),""))),ISNUMBER(IFERROR(INDEX('Evaluation-1'!$L$6:$L$436,MATCH($A14&"|"&$E14,'Evaluation-1'!$P$6:$P$436,0)),IFERROR(INDEX('Evaluation-1'!$L$6:$L$436,MATCH($E14,'Evaluation-1'!$G$6:$G$436,0)),"")))),"Yes","No") -> Yes | Q14: =IF(L14<>"","Yes","No") -> No | R14: =IF('Mr. Akhilesh Kumar Srivastava'!M14="","",'Mr. Akhilesh Kumar Srivastava'!M14) | S14: =IF('Mr. Akhilesh Kumar Srivastava'!N14="","",'Mr. Akhilesh Kumar Srivastava'!N14) | T14: =IF('Mr. Akhilesh Kumar Srivastava'!O14="","",'Mr. Akhilesh Kumar Srivastava'!O14) | U14: =IF('Mr. Akhilesh Kumar Srivastava'!P14="","",'Mr. Akhilesh Kumar Srivastava'!P14) | V14: =IF('Mr. Akhilesh Kumar Srivastava'!Q14="","",'Mr. Akhilesh Kumar Srivastava'!Q14) | W14: =IF(COUNT(R14:V14)=0,"",SUM(R14:V14)) | X14: =IF('Mr. Akhilesh Kumar Srivastava'!S14="","",'Mr. Akhilesh Kumar Srivastava'!S14) | Y14: =IF('Mr. Akhilesh Kumar Srivastava'!T14="","",'Mr. Akhilesh Kumar Srivastava'!T14) | Z14: =IF('Mr. Akhilesh Kumar Srivastava'!U14="","",'Mr. Akhilesh Kumar Srivastava'!U14) | AA14: =IF('Mr. Akhilesh Kumar Srivastava'!V14="","",'Mr. Akhilesh Kumar Srivastava'!V14) | AB14: =IF('Mr. Akhilesh Kumar Srivastava'!W14="","",'Mr. Akhilesh Kumar Srivastava'!W14) | AC14: =IF(COUNT(X14:AB14)=0,"",SUM(X14:AB14)) | AD14: =IF(COUNT(M14,W14,AC14)=0,"",ROUND(SUM(M14,W14,AC14),2)) -> 4.8 | AE14: =IF(W14<>"","Yes","No") -> No | AF14: =IF(AC14<>"","Yes","No") -> No | AG14: =IF(A14<>"",A14,AG13) -> P_003 | AH14: =IF(B14<>"",B14,IF(A14<>"","",AH13)) | AI14: =IF(D14<>"",D14,AI13) -> Mr. Akhilesh Kumar Srivastava
E15: 2400320100865 | F15: Pushkar Goel | G15: =IFERROR(INDEX('Evaluation-1'!$N$6:$N$436,MATCH($A15&"|"&$E15,'Evaluation-1'!$P$6:$P$436,0)),IFERROR(INDEX('Evaluation-1'!$N$6:$N$436,MATCH($E15,'Evaluation-1'!$G$6:$G$436,0)),"")) -> 4.8 | H15: =IF('Mr. Akhilesh Kumar Srivastava'!F15="","",'Mr. Akhilesh Kumar Srivastava'!F15) | I15: =IF('Mr. Akhilesh Kumar Srivastava'!G15="","",'Mr. Akhilesh Kumar Srivastava'!G15) | J15: =IF('Mr. Akhilesh Kumar Srivastava'!H15="","",'Mr. Akhilesh Kumar Srivastava'!H15) | K15: =IF('Mr. Akhilesh Kumar Srivastava'!I15="","",'Mr. Akhilesh Kumar Srivastava'!I15) | L15: =IF(COUNT(H15:K15)=0,"",SUM(H15:K15)) | M15: =IF(COUNT(G15,L15)=0,"",ROUND(SUM(G15,L15),2)) -> 4.8 | N15: =IF($G15="","Not in Evaluation-1",IF(TRIM(LOWER(IFERROR(INDEX('Evaluation-1'!$H$6:$H$436,MATCH($A15&"|"&$E15,'Evaluation-1'!$P$6:$P$436,0)),INDEX('Evaluation-1'!$H$6:$H$436,MATCH($E15,'Evaluation-1'!$G$6:$G$436,0)))))=TRIM(LOWER($F15)),"OK","CHECK NAME")) -> OK | O15: =IF(C15<>"",C15,O14) -> Mr. Abhishek Yadav | P15: =IF(OR(ISNUMBER(IFERROR(INDEX('Evaluation-1'!$K$6:$K$436,MATCH($A15&"|"&$E15,'Evaluation-1'!$P$6:$P$436,0)),IFERROR(INDEX('Evaluation-1'!$K$6:$K$436,MATCH($E15,'Evaluation-1'!$G$6:$G$436,0)),""))),ISNUMBER(IFERROR(INDEX('Evaluation-1'!$L$6:$L$436,MATCH($A15&"|"&$E15,'Evaluation-1'!$P$6:$P$436,0)),IFERROR(INDEX('Evaluation-1'!$L$6:$L$436,MATCH($E15,'Evaluation-1'!$G$6:$G$436,0)),"")))),"Yes","No") -> Yes | Q15: =IF(L15<>"","Yes","No") -> No | R15: =IF('Mr. Akhilesh Kumar Srivastava'!M15="","",'Mr. Akhilesh Kumar Srivastava'!M15) | S15: =IF('Mr. Akhilesh Kumar Srivastava'!N15="","",'Mr. Akhilesh Kumar Srivastava'!N15) | T15: =IF('Mr. Akhilesh Kumar Srivastava'!O15="","",'Mr. Akhilesh Kumar Srivastava'!O15) | U15: =IF('Mr. Akhilesh Kumar Srivastava'!P15="","",'Mr. Akhilesh Kumar Srivastava'!P15) | V15: =IF('Mr. Akhilesh Kumar Srivastava'!Q15="","",'Mr. Akhilesh Kumar Srivastava'!Q15) | W15: =IF(COUNT(R15:V15)=0,"",SUM(R15:V15)) | X15: =IF('Mr. Akhilesh Kumar Srivastava'!S15="","",'Mr. Akhilesh Kumar Srivastava'!S15) | Y15: =IF('Mr. Akhilesh Kumar Srivastava'!T15="","",'Mr. Akhilesh Kumar Srivastava'!T15) | Z15: =IF('Mr. Akhilesh Kumar Srivastava'!U15="","",'Mr. Akhilesh Kumar Srivastava'!U15) | AA15: =IF('Mr. Akhilesh Kumar Srivastava'!V15="","",'Mr. Akhilesh Kumar Srivastava'!V15) | AB15: =IF('Mr. Akhilesh Kumar Srivastava'!W15="","",'Mr. Akhilesh Kumar Srivastava'!W15) | AC15: =IF(COUNT(X15:AB15)=0,"",SUM(X15:AB15)) | AD15: =IF(COUNT(M15,W15,AC15)=0,"",ROUND(SUM(M15,W15,AC15),2)) -> 4.8 | AE15: =IF(W15<>"","Yes","No") -> No | AF15: =IF(AC15<>"","Yes","No") -> No | AG15: =IF(A15<>"",A15,AG14) -> P_003 | AH15: =IF(B15<>"",B15,IF(A15<>"","",AH14)) | AI15: =IF(D15<>"",D15,AI14) -> Mr. Akhilesh Kumar Srivastava
A16: P_004 | B16: =IF('Mr. Akhilesh Kumar Srivastava'!B16="","",'Mr. Akhilesh Kumar Srivastava'!B16) | E16: 2400320100659 | F16: Manish Jha | G16: =IFERROR(INDEX('Evaluation-1'!$N$6:$N$436,MATCH($A16&"|"&$E16,'Evaluation-1'!$P$6:$P$436,0)),IFERROR(INDEX('Evaluation-1'!$N$6:$N$436,MATCH($E16,'Evaluation-1'!$G$6:$G$436,0)),"")) -> 0 | H16: =IF('Mr. Akhilesh Kumar Srivastava'!F16="","",'Mr. Akhilesh Kumar Srivastava'!F16) | I16: =IF('Mr. Akhilesh Kumar Srivastava'!G16="","",'Mr. Akhilesh Kumar Srivastava'!G16) | J16: =IF('Mr. Akhilesh Kumar Srivastava'!H16="","",'Mr. Akhilesh Kumar Srivastava'!H16) | K16: =IF('Mr. Akhilesh Kumar Srivastava'!I16="","",'Mr. Akhilesh Kumar Srivastava'!I16) | L16: =IF(COUNT(H16:K16)=0,"",SUM(H16:K16)) | M16: =IF(COUNT(G16,L16)=0,"",ROUND(SUM(G16,L16),2)) -> 0 | N16: =IF($G16="","Not in Evaluation-1",IF(TRIM(LOWER(IFERROR(INDEX('Evaluation-1'!$H$6:$H$436,MATCH($A16&"|"&$E16,'Evaluation-1'!$P$6:$P$436,0)),INDEX('Evaluation-1'!$H$6:$H$436,MATCH($E16,'Evaluation-1'!$G$6:$G$436,0)))))=TRIM(LOWER($F16)),"OK","CHECK NAME")) -> OK | O16: =IF(C16<>"",C16,O15) -> Mr. Abhishek Yadav | P16: =IF(OR(ISNUMBER(IFERROR(INDEX('Evaluation-1'!$K$6:$K$436,MATCH($A16&"|"&$E16,'Evaluation-1'!$P$6:$P$436,0)),IFERROR(INDEX('Evaluation-1'!$K$6:$K$436,MATCH($E16,'Evaluation-1'!$G$6:$G$436,0)),""))),ISNUMBER(IFERROR(INDEX('Evaluation-1'!$L$6:$L$436,MATCH($A16&"|"&$E16,'Evaluation-1'!$P$6:$P$436,0)),IFERROR(INDEX('Evaluation-1'!$L$6:$L$436,MATCH($E16,'Evaluation-1'!$G$6:$G$436,0)),"")))),"Yes","No") -> Yes | Q16: =IF(L16<>"","Yes","No") -> No | R16: =IF('Mr. Akhilesh Kumar Srivastava'!M16="","",'Mr. Akhilesh Kumar Srivastava'!M16) | S16: =IF('Mr. Akhilesh Kumar Srivastava'!N16="","",'Mr. Akhilesh Kumar Srivastava'!N16) | T16: =IF('Mr. Akhilesh Kumar Srivastava'!O16="","",'Mr. Akhilesh Kumar Srivastava'!O16) | U16: =IF('Mr. Akhilesh Kumar Srivastava'!P16="","",'Mr. Akhilesh Kumar Srivastava'!P16) | V16: =IF('Mr. Akhilesh Kumar Srivastava'!Q16="","",'Mr. Akhilesh Kumar Srivastava'!Q16) | W16: =IF(COUNT(R16:V16)=0,"",SUM(R16:V16)) | X16: =IF('Mr. Akhilesh Kumar Srivastava'!S16="","",'Mr. Akhilesh Kumar Srivastava'!S16) | Y16: =IF('Mr. Akhilesh Kumar Srivastava'!T16="","",'Mr. Akhilesh Kumar Srivastava'!T16) | Z16: =IF('Mr. Akhilesh Kumar Srivastava'!U16="","",'Mr. Akhilesh Kumar Srivastava'!U16) | AA16: =IF('Mr. Akhilesh Kumar Srivastava'!V16="","",'Mr. Akhilesh Kumar Srivastava'!V16) | AB16: =IF('Mr. Akhilesh Kumar Srivastava'!W16="","",'Mr. Akhilesh Kumar Srivastava'!W16) | AC16: =IF(COUNT(X16:AB16)=0,"",SUM(X16:AB16)) | AD16: =IF(COUNT(M16,W16,AC16)=0,"",ROUND(SUM(M16,W16,AC16),2)) -> 0 | AE16: =IF(W16<>"","Yes","No") -> No | AF16: =IF(AC16<>"","Yes","No") -> No | AG16: =IF(A16<>"",A16,AG15) -> P_004 | AH16: =IF(B16<>"",B16,IF(A16<>"","",AH15)) | AI16: =IF(D16<>"",D16,AI15) -> Mr. Akhilesh Kumar Srivastava
E17: 2400320100658 | F17: Mani Aggarwal | G17: =IFERROR(INDEX('Evaluation-1'!$N$6:$N$436,MATCH($A17&"|"&$E17,'Evaluation-1'!$P$6:$P$436,0)),IFERROR(INDEX('Evaluation-1'!$N$6:$N$436,MATCH($E17,'Evaluation-1'!$G$6:$G$436,0)),"")) -> 0 | H17: =IF('Mr. Akhilesh Kumar Srivastava'!F17="","",'Mr. Akhilesh Kumar Srivastava'!F17) | I17: =IF('Mr. Akhilesh Kumar Srivastava'!G17="","",'Mr. Akhilesh Kumar Srivastava'!G17) | J17: =IF('Mr. Akhilesh Kumar Srivastava'!H17="","",'Mr. Akhilesh Kumar Srivastava'!H17) | K17: =IF('Mr. Akhilesh Kumar Srivastava'!I17="","",'Mr. Akhilesh Kumar Srivastava'!I17) | L17: =IF(COUNT(H17:K17)=0,"",SUM(H17:K17)) | M17: =IF(COUNT(G17,L17)=0,"",ROUND(SUM(G17,L17),2)) -> 0 | N17: =IF($G17="","Not in Evaluation-1",IF(TRIM(LOWER(IFERROR(INDEX('Evaluation-1'!$H$6:$H$436,MATCH($A17&"|"&$E17,'Evaluation-1'!$P$6:$P$436,0)),INDEX('Evaluation-1'!$H$6:$H$436,MATCH($E17,'Evaluation-1'!$G$6:$G$436,0)))))=TRIM(LOWER($F17)),"OK","CHECK NAME")) -> OK | O17: =IF(C17<>"",C17,O16) -> Mr. Abhishek Yadav | P17: =IF(OR(ISNUMBER(IFERROR(INDEX('Evaluation-1'!$K$6:$K$436,MATCH($A17&"|"&$E17,'Evaluation-1'!$P$6:$P$436,0)),IFERROR(INDEX('Evaluation-1'!$K$6:$K$436,MATCH($E17,'Evaluation-1'!$G$6:$G$436,0)),""))),ISNUMBER(IFERROR(INDEX('Evaluation-1'!$L$6:$L$436,MATCH($A17&"|"&$E17,'Evaluation-1'!$P$6:$P$436,0)),IFERROR(INDEX('Evaluation-1'!$L$6:$L$436,MATCH($E17,'Evaluation-1'!$G$6:$G$436,0)),"")))),"Yes","No") -> Yes | Q17: =IF(L17<>"","Yes","No") -> No | R17: =IF('Mr. Akhilesh Kumar Srivastava'!M17="","",'Mr. Akhilesh Kumar Srivastava'!M17) | S17: =IF('Mr. Akhilesh Kumar Srivastava'!N17="","",'Mr. Akhilesh Kumar Srivastava'!N17) | T17: =IF('Mr. Akhilesh Kumar Srivastava'!O17="","",'Mr. Akhilesh Kumar Srivastava'!O17) | U17: =IF('Mr. Akhilesh Kumar Srivastava'!P17="","",'Mr. Akhilesh Kumar Srivastava'!P17) | V17: =IF('Mr. Akhilesh Kumar Srivastava'!Q17="","",'Mr. Akhilesh Kumar Srivastava'!Q17) | W17: =IF(COUNT(R17:V17)=0,"",SUM(R17:V17)) | X17: =IF('Mr. Akhilesh Kumar Srivastava'!S17="","",'Mr. Akhilesh Kumar Srivastava'!S17) | Y17: =IF('Mr. Akhilesh Kumar Srivastava'!T17="","",'Mr. Akhilesh Kumar Srivastava'!T17) | Z17: =IF('Mr. Akhilesh Kumar Srivastava'!U17="","",'Mr. Akhilesh Kumar Srivastava'!U17) | AA17: =IF('Mr. Akhilesh Kumar Srivastava'!V17="","",'Mr. Akhilesh Kumar Srivastava'!V17) | AB17: =IF('Mr. Akhilesh Kumar Srivastava'!W17="","",'Mr. Akhilesh Kumar Srivastava'!W17) | AC17: =IF(COUNT(X17:AB17)=0,"",SUM(X17:AB17)) | AD17: =IF(COUNT(M17,W17,AC17)=0,"",ROUND(SUM(M17,W17,AC17),2)) -> 0 | AE17: =IF(W17<>"","Yes","No") -> No | AF17: =IF(AC17<>"","Yes","No") -> No | AG17: =IF(A17<>"",A17,AG16) -> P_004 | AH17: =IF(B17<>"",B17,IF(A17<>"","",AH16)) | AI17: =IF(D17<>"",D17,AI16) -> Mr. Akhilesh Kumar Srivastava
E18: 2400320100656 | F18: Masvi Dhiman | G18: =IFERROR(INDEX('Evaluation-1'!$N$6:$N$436,MATCH($A18&"|"&$E18,'Evaluation-1'!$P$6:$P$436,0)),IFERROR(INDEX('Evaluation-1'!$N$6:$N$436,MATCH($E18,'Evaluation-1'!$G$6:$G$436,0)),"")) -> 0 | H18: =IF('Mr. Akhilesh Kumar Srivastava'!F18="","",'Mr. Akhilesh Kumar Srivastava'!F18) | I18: =IF('Mr. Akhilesh Kumar Srivastava'!G18="","",'Mr. Akhilesh Kumar Srivastava'!G18) | J18: =IF('Mr. Akhilesh Kumar Srivastava'!H18="","",'Mr. Akhilesh Kumar Srivastava'!H18) | K18: =IF('Mr. Akhilesh Kumar Srivastava'!I18="","",'Mr. Akhilesh Kumar Srivastava'!I18) | L18: =IF(COUNT(H18:K18)=0,"",SUM(H18:K18)) | M18: =IF(COUNT(G18,L18)=0,"",ROUND(SUM(G18,L18),2)) -> 0 | N18: =IF($G18="","Not in Evaluation-1",IF(TRIM(LOWER(IFERROR(INDEX('Evaluation-1'!$H$6:$H$436,MATCH($A18&"|"&$E18,'Evaluation-1'!$P$6:$P$436,0)),INDEX('Evaluation-1'!$H$6:$H$436,MATCH($E18,'Evaluation-1'!$G$6:$G$436,0)))))=TRIM(LOWER($F18)),"OK","CHECK NAME")) -> OK | O18: =IF(C18<>"",C18,O17) -> Mr. Abhishek Yadav | P18: =IF(OR(ISNUMBER(IFERROR(INDEX('Evaluation-1'!$K$6:$K$436,MATCH($A18&"|"&$E18,'Evaluation-1'!$P$6:$P$436,0)),IFERROR(INDEX('Evaluation-1'!$K$6:$K$436,MATCH($E18,'Evaluation-1'!$G$6:$G$436,0)),""))),ISNUMBER(IFERROR(INDEX('Evaluation-1'!$L$6:$L$436,MATCH($A18&"|"&$E18,'Evaluation-1'!$P$6:$P$436,0)),IFERROR(INDEX('Evaluation-1'!$L$6:$L$436,MATCH($E18,'Evaluation-1'!$G$6:$G$436,0)),"")))),"Yes","No") -> Yes | Q18: =IF(L18<>"","Yes","No") -> No | R18: =IF('Mr. Akhilesh Kumar Srivastava'!M18="","",'Mr. Akhilesh Kumar Srivastava'!M18) | S18: =IF('Mr. Akhilesh Kumar Srivastava'!N18="","",'Mr. Akhilesh Kumar Srivastava'!N18) | T18: =IF('Mr. Akhilesh Kumar Srivastava'!O18="","",'Mr. Akhilesh Kumar Srivastava'!O18) | U18: =IF('Mr. Akhilesh Kumar Srivastava'!P18="","",'Mr. Akhilesh Kumar Srivastava'!P18) | V18: =IF('Mr. Akhilesh Kumar Srivastava'!Q18="","",'Mr. Akhilesh Kumar Srivastava'!Q18) | W18: =IF(COUNT(R18:V18)=0,"",SUM(R18:V18)) | X18: =IF('Mr. Akhilesh Kumar Srivastava'!S18="","",'Mr. Akhilesh Kumar Srivastava'!S18) | Y18: =IF('Mr. Akhilesh Kumar Srivastava'!T18="","",'Mr. Akhilesh Kumar Srivastava'!T18) | Z18: =IF('Mr. Akhilesh Kumar Srivastava'!U18="","",'Mr. Akhilesh Kumar Srivastava'!U18) | AA18: =IF('Mr. Akhilesh Kumar Srivastava'!V18="","",'Mr. Akhilesh Kumar Srivastava'!V18) | AB18: =IF('Mr. Akhilesh Kumar Srivastava'!W18="","",'Mr. Akhilesh Kumar Srivastava'!W18) | AC18: =IF(COUNT(X18:AB18)=0,"",SUM(X18:AB18)) | AD18: =IF(COUNT(M18,W18,AC18)=0,"",ROUND(SUM(M18,W18,AC18),2)) -> 0 | AE18: =IF(W18<>"","Yes","No") -> No | AF18: =IF(AC18<>"","Yes","No") -> No | AG18: =IF(A18<>"",A18,AG17) -> P_004 | AH18: =IF(B18<>"",B18,IF(A18<>"","",AH17)) | AI18: =IF(D18<>"",D18,AI17) -> Mr. Akhilesh Kumar Srivastava
E19: 2400320100712 | F19: Mudit Chaturvedi | G19: =IFERROR(INDEX('Evaluation-1'!$N$6:$N$436,MATCH($A19&"|"&$E19,'Evaluation-1'!$P$6:$P$436,0)),IFERROR(INDEX('Evaluation-1'!$N$6:$N$436,MATCH($E19,'Evaluation-1'!$G$6:$G$436,0)),"")) -> 0 | H19: =IF('Mr. Akhilesh Kumar Srivastava'!F19="","",'Mr. Akhilesh Kumar Srivastava'!F19) | I19: =IF('Mr. Akhilesh Kumar Srivastava'!G19="","",'Mr. Akhilesh Kumar Srivastava'!G19) | J19: =IF('Mr. Akhilesh Kumar Srivastava'!H19="","",'Mr. Akhilesh Kumar Srivastava'!H19) | K19: =IF('Mr. Akhilesh Kumar Srivastava'!I19="","",'Mr. Akhilesh Kumar Srivastava'!I19) | L19: =IF(COUNT(H19:K19)=0,"",SUM(H19:K19)) | M19: =IF(COUNT(G19,L19)=0,"",ROUND(SUM(G19,L19),2)) -> 0 | N19: =IF($G19="","Not in Evaluation-1",IF(TRIM(LOWER(IFERROR(INDEX('Evaluation-1'!$H$6:$H$436,MATCH($A19&"|"&$E19,'Evaluation-1'!$P$6:$P$436,0)),INDEX('Evaluation-1'!$H$6:$H$436,MATCH($E19,'Evaluation-1'!$G$6:$G$436,0)))))=TRIM(LOWER($F19)),"OK","CHECK NAME")) -> OK | O19: =IF(C19<>"",C19,O18) -> Mr. Abhishek Yadav | P19: =IF(OR(ISNUMBER(IFERROR(INDEX('Evaluation-1'!$K$6:$K$436,MATCH($A19&"|"&$E19,'Evaluation-1'!$P$6:$P$436,0)),IFERROR(INDEX('Evaluation-1'!$K$6:$K$436,MATCH($E19,'Evaluation-1'!$G$6:$G$436,0)),""))),ISNUMBER(IFERROR(INDEX('Evaluation-1'!$L$6:$L$436,MATCH($A19&"|"&$E19,'Evaluation-1'!$P$6:$P$436,0)),IFERROR(INDEX('Evaluation-1'!$L$6:$L$436,MATCH($E19,'Evaluation-1'!$G$6:$G$436,0)),"")))),"Yes","No") -> Yes | Q19: =IF(L19<>"","Yes","No") -> No | R19: =IF('Mr. Akhilesh Kumar Srivastava'!M19="","",'Mr. Akhilesh Kumar Srivastava'!M19) | S19: =IF('Mr. Akhilesh Kumar Srivastava'!N19="","",'Mr. Akhilesh Kumar Srivastava'!N19) | T19: =IF('Mr. Akhilesh Kumar Srivastava'!O19="","",'Mr. Akhilesh Kumar Srivastava'!O19) | U19: =IF('Mr. Akhilesh Kumar Srivastava'!P19="","",'Mr. Akhilesh Kumar Srivastava'!P19) | V19: =IF('Mr. Akhilesh Kumar Srivastava'!Q19="","",'Mr. Akhilesh Kumar Srivastava'!Q19) | W19: =IF(COUNT(R19:V19)=0,"",SUM(R19:V19)) | X19: =IF('Mr. Akhilesh Kumar Srivastava'!S19="","",'Mr. Akhilesh Kumar Srivastava'!S19) | Y19: =IF('Mr. Akhilesh Kumar Srivastava'!T19="","",'Mr. Akhilesh Kumar Srivastava'!T19) | Z19: =IF('Mr. Akhilesh Kumar Srivastava'!U19="","",'Mr. Akhilesh Kumar Srivastava'!U19) | AA19: =IF('Mr. Akhilesh Kumar Srivastava'!V19="","",'Mr. Akhilesh Kumar Srivastava'!V19) | AB19: =IF('Mr. Akhilesh Kumar Srivastava'!W19="","",'Mr. Akhilesh Kumar Srivastava'!W19) | AC19: =IF(COUNT(X19:AB19)=0,"",SUM(X19:AB19)) | AD19: =IF(COUNT(M19,W19,AC19)=0,"",ROUND(SUM(M19,W19,AC19),2)) -> 0 | AE19: =IF(W19<>"","Yes","No") -> No | AF19: =IF(AC19<>"","Yes","No") -> No | AG19: =IF(A19<>"",A19,AG18) -> P_004 | AH19: =IF(B19<>"",B19,IF(A19<>"","",AH18)) | AI19: =IF(D19<>"",D19,AI18) -> Mr. Akhilesh Kumar Srivastava
A20: P_005 | B20: =IF('Ms. Ayushi Agarwal'!B4="","",'Ms. Ayushi Agarwal'!B4) | C20: Mr. Akhilesh Kumar Srivastava | D20: Ms. Ayushi Agarwal | E20: 2400320100603 | F20: Khushi Tyagi | G20: =IFERROR(INDEX('Evaluation-1'!$N$6:$N$436,MATCH($A20&"|"&$E20,'Evaluation-1'!$P$6:$P$436,0)),IFERROR(INDEX('Evaluation-1'!$N$6:$N$436,MATCH($E20,'Evaluation-1'!$G$6:$G$436,0)),"")) -> 0 | H20: =IF('Ms. Ayushi Agarwal'!F4="","",'Ms. Ayushi Agarwal'!F4) | I20: =IF('Ms. Ayushi Agarwal'!G4="","",'Ms. Ayushi Agarwal'!G4) | J20: =IF('Ms. Ayushi Agarwal'!H4="","",'Ms. Ayushi Agarwal'!H4) | K20: =IF('Ms. Ayushi Agarwal'!I4="","",'Ms. Ayushi Agarwal'!I4) | L20: =IF(COUNT(H20:K20)=0,"",SUM(H20:K20)) | M20: =IF(COUNT(G20,L20)=0,"",ROUND(SUM(G20,L20),2)) -> 0 | N20: =IF($G20="","Not in Evaluation-1",IF(TRIM(LOWER(IFERROR(INDEX('Evaluation-1'!$H$6:$H$436,MATCH($A20&"|"&$E20,'Evaluation-1'!$P$6:$P$436,0)),INDEX('Evaluation-1'!$H$6:$H$436,MATCH($E20,'Evaluation-1'!$G$6:$G$436,0)))))=TRIM(LOWER($F20)),"OK","CHECK NAME")) -> OK | O20: =IF(C20<>"",C20,O19) -> Mr. Akhilesh Kumar Srivastava | P20: =IF(OR(ISNUMBER(IFERROR(INDEX('Evaluation-1'!$K$6:$K$436,MATCH($A20&"|"&$E20,'Evaluation-1'!$P$6:$P$436,0)),IFERROR(INDEX('Evaluation-1'!$K$6:$K$436,MATCH($E20,'Evaluation-1'!$G$6:$G$436,0)),""))),ISNUMBER(IFERROR(INDEX('Evaluation-1'!$L$6:$L$436,MATCH($A20&"|"&$E20,'Evaluation-1'!$P$6:$P$436,0)),IFERROR(INDEX('Evaluation-1'!$L$6:$L$436,MATCH($E20,'Evaluation-1'!$G$6:$G$436,0)),"")))),"Yes","No") -> Yes | Q20: =IF(L20<>"","Yes","No") -> No | R20: =IF('Ms. Ayushi Agarwal'!M4="","",'Ms. Ayushi Agarwal'!M4) | S20: =IF('Ms. Ayushi Agarwal'!N4="","",'Ms. Ayushi Agarwal'!N4) | T20: =IF('Ms. Ayushi Agarwal'!O4="","",'Ms. Ayushi Agarwal'!O4) | U20: =IF('Ms. Ayushi Agarwal'!P4="","",'Ms. Ayushi Agarwal'!P4) | V20: =IF('Ms. Ayushi Agarwal'!Q4="","",'Ms. Ayushi Agarwal'!Q4) | W20: =IF(COUNT(R20:V20)=0,"",SUM(R20:V20)) | X20: =IF('Ms. Ayushi Agarwal'!S4="","",'Ms. Ayushi Agarwal'!S4) | Y20: =IF('Ms. Ayushi Agarwal'!T4="","",'Ms. Ayushi Agarwal'!T4) | Z20: =IF('Ms. Ayushi Agarwal'!U4="","",'Ms. Ayushi Agarwal'!U4) | AA20: =IF('Ms. Ayushi Agarwal'!V4="","",'Ms. Ayushi Agarwal'!V4) | AB20: =IF('Ms. Ayushi Agarwal'!W4="","",'Ms. Ayushi Agarwal'!W4) | AC20: =IF(COUNT(X20:AB20)=0,"",SUM(X20:AB20)) | AD20: =IF(COUNT(M20,W20,AC20)=0,"",ROUND(SUM(M20,W20,AC20),2)) -> 0 | AE20: =IF(W20<>"","Yes","No") -> No | AF20: =IF(AC20<>"","Yes","No") -> No | AG20: =IF(A20<>"",A20,AG19) -> P_005 | AH20: =IF(B20<>"",B20,IF(A20<>"","",AH19)) | AI20: =IF(D20<>"",D20,AI19) -> Ms. Ayushi Agarwal
E21: 2400320100610 | F21: Krish Bansal | G21: =IFERROR(INDEX('Evaluation-1'!$N$6:$N$436,MATCH($A21&"|"&$E21,'Evaluation-1'!$P$6:$P$436,0)),IFERROR(INDEX('Evaluation-1'!$N$6:$N$436,MATCH($E21,'Evaluation-1'!$G$6:$G$436,0)),"")) -> 0 | H21: =IF('Ms. Ayushi Agarwal'!F5="","",'Ms. Ayushi Agarwal'!F5) | I21: =IF('Ms. Ayushi Agarwal'!G5="","",'Ms. Ayushi Agarwal'!G5) | J21: =IF('Ms. Ayushi Agarwal'!H5="","",'Ms. Ayushi Agarwal'!H5) | K21: =IF('Ms. Ayushi Agarwal'!I5="","",'Ms. Ayushi Agarwal'!I5) | L21: =IF(COUNT(H21:K21)=0,"",SUM(H21:K21)) | M21: =IF(COUNT(G21,L21)=0,"",ROUND(SUM(G21,L21),2)) -> 0 | N21: =IF($G21="","Not in Evaluation-1",IF(TRIM(LOWER(IFERROR(INDEX('Evaluation-1'!$H$6:$H$436,MATCH($A21&"|"&$E21,'Evaluation-1'!$P$6:$P$436,0)),INDEX('Evaluation-1'!$H$6:$H$436,MATCH($E21,'Evaluation-1'!$G$6:$G$436,0)))))=TRIM(LOWER($F21)),"OK","CHECK NAME")) -> OK | O21: =IF(C21<>"",C21,O20) -> Mr. Akhilesh Kumar Srivastava | P21: =IF(OR(ISNUMBER(IFERROR(INDEX('Evaluation-1'!$K$6:$K$436,MATCH($A21&"|"&$E21,'Evaluation-1'!$P$6:$P$436,0)),IFERROR(INDEX('Evaluation-1'!$K$6:$K$436,MATCH($E21,'Evaluation-1'!$G$6:$G$436,0)),""))),ISNUMBER(IFERROR(INDEX('Evaluation-1'!$L$6:$L$436,MATCH($A21&"|"&$E21,'Evaluation-1'!$P$6:$P$436,0)),IFERROR(INDEX('Evaluation-1'!$L$6:$L$436,MATCH($E21,'Evaluation-1'!$G$6:$G$436,0)),"")))),"Yes","No") -> Yes | Q21: =IF(L21<>"","Yes","No") -> No | R21: =IF('Ms. Ayushi Agarwal'!M5="","",'Ms. Ayushi Agarwal'!M5) | S21: =IF('Ms. Ayushi Agarwal'!N5="","",'Ms. Ayushi Agarwal'!N5) | T21: =IF('Ms. Ayushi Agarwal'!O5="","",'Ms. Ayushi Agarwal'!O5) | U21: =IF('Ms. Ayushi Agarwal'!P5="","",'Ms. Ayushi Agarwal'!P5) | V21: =IF('Ms. Ayushi Agarwal'!Q5="","",'Ms. Ayushi Agarwal'!Q5) | W21: =IF(COUNT(R21:V21)=0,"",SUM(R21:V21)) | X21: =IF('Ms. Ayushi Agarwal'!S5="","",'Ms. Ayushi Agarwal'!S5) | Y21: =IF('Ms. Ayushi Agarwal'!T5="","",'Ms. Ayushi Agarwal'!T5) | Z21: =IF('Ms. Ayushi Agarwal'!U5="","",'Ms. Ayushi Agarwal'!U5) | AA21: =IF('Ms. Ayushi Agarwal'!V5="","",'Ms. Ayushi Agarwal'!V5) | AB21: =IF('Ms. Ayushi Agarwal'!W5="","",'Ms. Ayushi Agarwal'!W5) | AC21: =IF(COUNT(X21:AB21)=0,"",SUM(X21:AB21)) | AD21: =IF(COUNT(M21,W21,AC21)=0,"",ROUND(SUM(M21,W21,AC21),2)) -> 0 | AE21: =IF(W21<>"","Yes","No") -> No | AF21: =IF(AC21<>"","Yes","No") -> No | AG21: =IF(A21<>"",A21,AG20) -> P_005 | AH21: =IF(B21<>"",B21,IF(A21<>"","",AH20)) | AI21: =IF(D21<>"",D21,AI20) -> Ms. Ayushi Agarwal
E22: 2400320100596 | F22: Khushi Jain | G22: =IFERROR(INDEX('Evaluation-1'!$N$6:$N$436,MATCH($A22&"|"&$E22,'Evaluation-1'!$P$6:$P$436,0)),IFERROR(INDEX('Evaluation-1'!$N$6:$N$436,MATCH($E22,'Evaluation-1'!$G$6:$G$436,0)),"")) -> 0 | H22: =IF('Ms. Ayushi Agarwal'!F6="","",'Ms. Ayushi Agarwal'!F6) | I22: =IF('Ms. Ayushi Agarwal'!G6="","",'Ms. Ayushi Agarwal'!G6) | J22: =IF('Ms. Ayushi Agarwal'!H6="","",'Ms. Ayushi Agarwal'!H6) | K22: =IF('Ms. Ayushi Agarwal'!I6="","",'Ms. Ayushi Agarwal'!I6) | L22: =IF(COUNT(H22:K22)=0,"",SUM(H22:K22)) | M22: =IF(COUNT(G22,L22)=0,"",ROUND(SUM(G22,L22),2)) -> 0 | N22: =IF($G22="","Not in Evaluation-1",IF(TRIM(LOWER(IFERROR(INDEX('Evaluation-1'!$H$6:$H$436,MATCH($A22&"|"&$E22,'Evaluation-1'!$P$6:$P$436,0)),INDEX('Evaluation-1'!$H$6:$H$436,MATCH($E22,'Evaluation-1'!$G$6:$G$436,0)))))=TRIM(LOWER($F22)),"OK","CHECK NAME")) -> OK | O22: =IF(C22<>"",C22,O21) -> Mr. Akhilesh Kumar Srivastava | P22: =IF(OR(ISNUMBER(IFERROR(INDEX('Evaluation-1'!$K$6:$K$436,MATCH($A22&"|"&$E22,'Evaluation-1'!$P$6:$P$436,0)),IFERROR(INDEX('Evaluation-1'!$K$6:$K$436,MATCH($E22,'Evaluation-1'!$G$6:$G$436,0)),""))),ISNUMBER(IFERROR(INDEX('Evaluation-1'!$L$6:$L$436,MATCH($A22&"|"&$E22,'Evaluation-1'!$P$6:$P$436,0)),IFERROR(INDEX('Evaluation-1'!$L$6:$L$436,MATCH($E22,'Evaluation-1'!$G$6:$G$436,0)),"")))),"Yes","No") -> Yes | Q22: =IF(L22<>"","Yes","No") -> No | R22: =IF('Ms. Ayushi Agarwal'!M6="","",'Ms. Ayushi Agarwal'!M6) | S22: =IF('Ms. Ayushi Agarwal'!N6="","",'Ms. Ayushi Agarwal'!N6) | T22: =IF('Ms. Ayushi Agarwal'!O6="","",'Ms. Ayushi Agarwal'!O6) | U22: =IF('Ms. Ayushi Agarwal'!P6="","",'Ms. Ayushi Agarwal'!P6) | V22: =IF('Ms. Ayushi Agarwal'!Q6="","",'Ms. Ayushi Agarwal'!Q6) | W22: =IF(COUNT(R22:V22)=0,"",SUM(R22:V22)) | X22: =IF('Ms. Ayushi Agarwal'!S6="","",'Ms. Ayushi Agarwal'!S6) | Y22: =IF('Ms. Ayushi Agarwal'!T6="","",'Ms. Ayushi Agarwal'!T6) | Z22: =IF('Ms. Ayushi Agarwal'!U6="","",'Ms. Ayushi Agarwal'!U6) | AA22: =IF('Ms. Ayushi Agarwal'!V6="","",'Ms. Ayushi Agarwal'!V6) | AB22: =IF('Ms. Ayushi Agarwal'!W6="","",'Ms. Ayushi Agarwal'!W6) | AC22: =IF(COUNT(X22:AB22)=0,"",SUM(X22:AB22)) | AD22: =IF(COUNT(M22,W22,AC22)=0,"",ROUND(SUM(M22,W22,AC22),2)) -> 0 | AE22: =IF(W22<>"","Yes","No") -> No | AF22: =IF(AC22<>"","Yes","No") -> No | AG22: =IF(A22<>"",A22,AG21) -> P_005 | AH22: =IF(B22<>"",B22,IF(A22<>"","",AH21)) | AI22: =IF(D22<>"",D22,AI21) -> Ms. Ayushi Agarwal
E23: 2400320100594 | F23: Khushi | G23: =IFERROR(INDEX('Evaluation-1'!$N$6:$N$436,MATCH($A23&"|"&$E23,'Evaluation-1'!$P$6:$P$436,0)),IFERROR(INDEX('Evaluation-1'!$N$6:$N$436,MATCH($E23,'Evaluation-1'!$G$6:$G$436,0)),"")) -> 0 | H23: =IF('Ms. Ayushi Agarwal'!F7="","",'Ms. Ayushi Agarwal'!F7) | I23: =IF('Ms. Ayushi Agarwal'!G7="","",'Ms. Ayushi Agarwal'!G7) | J23: =IF('Ms. Ayushi Agarwal'!H7="","",'Ms. Ayushi Agarwal'!H7) | K23: =IF('Ms. Ayushi Agarwal'!I7="","",'Ms. Ayushi Agarwal'!I7) | L23: =IF(COUNT(H23:K23)=0,"",SUM(H23:K23)) | M23: =IF(COUNT(G23,L23)=0,"",ROUND(SUM(G23,L23),2)) -> 0 | N23: =IF($G23="","Not in Evaluation-1",IF(TRIM(LOWER(IFERROR(INDEX('Evaluation-1'!$H$6:$H$436,MATCH($A23&"|"&$E23,'Evaluation-1'!$P$6:$P$436,0)),INDEX('Evaluation-1'!$H$6:$H$436,MATCH($E23,'Evaluation-1'!$G$6:$G$436,0)))))=TRIM(LOWER($F23)),"OK","CHECK NAME")) -> OK | O23: =IF(C23<>"",C23,O22) -> Mr. Akhilesh Kumar Srivastava | P23: =IF(OR(ISNUMBER(IFERROR(INDEX('Evaluation-1'!$K$6:$K$436,MATCH($A23&"|"&$E23,'Evaluation-1'!$P$6:$P$436,0)),IFERROR(INDEX('Evaluation-1'!$K$6:$K$436,MATCH($E23,'Evaluation-1'!$G$6:$G$436,0)),""))),ISNUMBER(IFERROR(INDEX('Evaluation-1'!$L$6:$L$436,MATCH($A23&"|"&$E23,'Evaluation-1'!$P$6:$P$436,0)),IFERROR(INDEX('Evaluation-1'!$L$6:$L$436,MATCH($E23,'Evaluation-1'!$G$6:$G$436,0)),"")))),"Yes","No") -> Yes | Q23: =IF(L23<>"","Yes","No") -> No | R23: =IF('Ms. Ayushi Agarwal'!M7="","",'Ms. Ayushi Agarwal'!M7) | S23: =IF('Ms. Ayushi Agarwal'!N7="","",'Ms. Ayushi Agarwal'!N7) | T23: =IF('Ms. Ayushi Agarwal'!O7="","",'Ms. Ayushi Agarwal'!O7) | U23: =IF('Ms. Ayushi Agarwal'!P7="","",'Ms. Ayushi Agarwal'!P7) | V23: =IF('Ms. Ayushi Agarwal'!Q7="","",'Ms. Ayushi Agarwal'!Q7) | W23: =IF(COUNT(R23:V23)=0,"",SUM(R23:V23)) | X23: =IF('Ms. Ayushi Agarwal'!S7="","",'Ms. Ayushi Agarwal'!S7) | Y23: =IF('Ms. Ayushi Agarwal'!T7="","",'Ms. Ayushi Agarwal'!T7) | Z23: =IF('Ms. Ayushi Agarwal'!U7="","",'Ms. Ayushi Agarwal'!U7) | AA23: =IF('Ms. Ayushi Agarwal'!V7="","",'Ms. Ayushi Agarwal'!V7) | AB23: =IF('Ms. Ayushi Agarwal'!W7="","",'Ms. Ayushi Agarwal'!W7) | AC23: =IF(COUNT(X23:AB23)=0,"",SUM(X23:AB23)) | AD23: =IF(COUNT(M23,W23,AC23)=0,"",ROUND(SUM(M23,W23,AC23),2)) -> 0 | AE23: =IF(W23<>"","Yes","No") -> No | AF23: =IF(AC23<>"","Yes","No") -> No | AG23: =IF(A23<>"",A23,AG22) -> P_005 | AH23: =IF(B23<>"",B23,IF(A23<>"","",AH22)) | AI23: =IF(D23<>"",D23,AI22) -> Ms. Ayushi Agarwal
A24: P_006 | B24: =IF('Ms. Ayushi Agarwal'!B8="","",'Ms. Ayushi Agarwal'!B8) | E24: 2400320100587 | F24: Kaustubh Sharma | G24: =IFERROR(INDEX('Evaluation-1'!$N$6:$N$436,MATCH($A24&"|"&$E24,'Evaluation-1'!$P$6:$P$436,0)),IFERROR(INDEX('Evaluation-1'!$N$6:$N$436,MATCH($E24,'Evaluation-1'!$G$6:$G$436,0)),"")) -> 5.4 | H24: =IF('Ms. Ayushi Agarwal'!F8="","",'Ms. Ayushi Agarwal'!F8) | I24: =IF('Ms. Ayushi Agarwal'!G8="","",'Ms. Ayushi Agarwal'!G8) | J24: =IF('Ms. Ayushi Agarwal'!H8="","",'Ms. Ayushi Agarwal'!H8) | K24: =IF('Ms. Ayushi Agarwal'!I8="","",'Ms. Ayushi Agarwal'!I8) | L24: =IF(COUNT(H24:K24)=0,"",SUM(H24:K24)) | M24: =IF(COUNT(G24,L24)=0,"",ROUND(SUM(G24,L24),2)) -> 5.4 | N24: =IF($G24="","Not in Evaluation-1",IF(TRIM(LOWER(IFERROR(INDEX('Evaluation-1'!$H$6:$H$436,MATCH($A24&"|"&$E24,'Evaluation-1'!$P$6:$P$436,0)),INDEX('Evaluation-1'!$H$6:$H$436,MATCH($E24,'Evaluation-1'!$G$6:$G$436,0)))))=TRIM(LOWER($F24)),"OK","CHECK NAME")) -> OK | O24: =IF(C24<>"",C24,O23) -> Mr. Akhilesh Kumar Srivastava | P24: =IF(OR(ISNUMBER(IFERROR(INDEX('Evaluation-1'!$K$6:$K$436,MATCH($A24&"|"&$E24,'Evaluation-1'!$P$6:$P$436,0)),IFERROR(INDEX('Evaluation-1'!$K$6:$K$436,MATCH($E24,'Evaluation-1'!$G$6:$G$436,0)),""))),ISNUMBER(IFERROR(INDEX('Evaluation-1'!$L$6:$L$436,MATCH($A24&"|"&$E24,'Evaluation-1'!$P$6:$P$436,0)),IFERROR(INDEX('Evaluation-1'!$L$6:$L$436,MATCH($E24,'Evaluation-1'!$G$6:$G$436,0)),"")))),"Yes","No") -> Yes | Q24: =IF(L24<>"","Yes","No") -> No | R24: =IF('Ms. Ayushi Agarwal'!M8="","",'Ms. Ayushi Agarwal'!M8) | S24: =IF('Ms. Ayushi Agarwal'!N8="","",'Ms. Ayushi Agarwal'!N8) | T24: =IF('Ms. Ayushi Agarwal'!O8="","",'Ms. Ayushi Agarwal'!O8) | U24: =IF('Ms. Ayushi Agarwal'!P8="","",'Ms. Ayushi Agarwal'!P8) | V24: =IF('Ms. Ayushi Agarwal'!Q8="","",'Ms. Ayushi Agarwal'!Q8) | W24: =IF(COUNT(R24:V24)=0,"",SUM(R24:V24)) | X24: =IF('Ms. Ayushi Agarwal'!S8="","",'Ms. Ayushi Agarwal'!S8) | Y24: =IF('Ms. Ayushi Agarwal'!T8="","",'Ms. Ayushi Agarwal'!T8) | Z24: =IF('Ms. Ayushi Agarwal'!U8="","",'Ms. Ayushi Agarwal'!U8) | AA24: =IF('Ms. Ayushi Agarwal'!V8="","",'Ms. Ayushi Agarwal'!V8) | AB24: =IF('Ms. Ayushi Agarwal'!W8="","",'Ms. Ayushi Agarwal'!W8) | AC24: =IF(COUNT(X24:AB24)=0,"",SUM(X24:AB24)) | AD24: =IF(COUNT(M24,W24,AC24)=0,"",ROUND(SUM(M24,W24,AC24),2)) -> 5.4 | AE24: =IF(W24<>"","Yes","No") -> No | AF24: =IF(AC24<>"","Yes","No") -> No | AG24: =IF(A24<>"",A24,AG23) -> P_006 | AH24: =IF(B24<>"",B24,IF(A24<>"","",AH23)) | AI24: =IF(D24<>"",D24,AI23) -> Ms. Ayushi Agarwal
